Workbook

Sheet Cover
B2: TATA MOTORS PASSENGER VEHICLES (TMPV)
B3: Integrated Three-Statement Financial Model & Valuation
B6: Company | C6: Tata Motors Passenger Vehicles Ltd (NSE: TMPV) | D6: BLUE - Constants
B7: Sector | C7: Automobiles — Passenger Vehicles + Jaguar Land Rover | D7: BLACK - Formulas (same sheet)
B8: Historical Period | C8: FY2015 – FY2026 (FY25–FY26 restated PV+JLR post demerger) | D8: GREEN - Links to other sheets
B9: Forecast Period | C9: FY2027E – FY2031E
B10: Valuation Methods | C10: Discounted Cash Flow (FCFF, primary) + Relative Valuation (cross-check)
B11: Prepared As On | C11: 20 August 2026
B12: Currency | C12: INR Crores unless stated otherwise
B13: Primary Data Sources | C13: screener.in (consolidated) · company FY26 disclosures
B15: Workbook Map
B16: Historical Data | C16: FY15–FY26 historical P&L, balance sheet, cash flow (screener.in consolidated)
B17: Ratio Analysis | C17: Profitability, leverage, efficiency, per-share & growth ratios FY26A–FY31E
B18: Assumptions | C18: All forecast drivers (blue cells = editable inputs)
B19: Working Capital Schedule | C19: Receivables / other assets / liabilities via days & %-of-revenue drivers
B20: Dep & Capex Schedule | C20: Net PP&E roll-forward: capex additions, depreciation
B21: Debt Schedule | C21: Borrowings roll-forward with cash sweep, auto-revolver and interest
B22: Income Statement | C22: Projected P&L FY27E–FY31E
B23: Balance Sheet | C23: Projected balance sheet (balances by construction; cash = CF plug)
B24: Cash Flow | C24: Projected cash flow (closing cash links back to balance sheet)
B25: Valuation | C25: DCF (FCFF, mid-year) + sensitivity + relative valuation + scenarios
B26: Recommendation | C26: Buy / Hold / Sell with rationale, risks and action triggers
B27: Checks | C27: Model controls: balance, cash, roll-forwards — all must show PASS
B29: KEY DATA NOTES
B30: Demerger — Effective 1-Oct-2025 the CV business was demerged; TMPV (PV + JLR) is the original listed company. FY15–FY24 history is the old combined Tata Motors; FY25–FY26 are restated PV+JLR.
B31: FY26 one-off — Other income includes a ₹86,291 Cr demerger-related exceptional gain; forecasts use normalized other income from Assumptions.
B32: JLR cyberattack — A Sep-2025 cyberattack shut JLR production ~5 weeks; FY26 revenue/margins are depressed and the forecast assumes recovery.
B33: Cash anchors — Screener lumps cash into 'Other Assets'; FY26 cash is derived from the disclosed net debt of ₹30,710 Cr.

Sheet Historical Data
A1: TMPV (TATA MOTORS PASSENGER VEHICLES) — HISTORICAL, FY15–FY26
B2: Source: screener.in consolidated (fetched 17-Aug-2026). ₹ Cr.
B4: PROFIT & LOSS
C5: FY15 | D5: FY16 | E5: FY17 | F5: FY18 | G5: FY19 | H5: FY20 | I5: FY21 | J5: FY22 | K5: FY23 | L5: FY24 | M5: FY25 | N5: FY26
B6: Sales | C6: 263159 | D6: 273046 | E6: 269693 | F6: 291550 | G6: 301938 | H6: 261068 | I6: 249795 | J6: 278454 | K6: 345967 | L6: 434016 | M6: 366094 | N6: 335582
B7: Expenses | C7: 223920 | D7: 234650 | E7: 240104 | F7: 260093 | G7: 277274 | H7: 243081 | I7: 217507 | J7: 253734 | K7: 314151 | L7: 376207 | M7: 318101 | N7: 316863
B8: Operating Profit (EBITDA) | C8: 39239 | D8: 38395 | E8: 29589 | F8: 31458 | G8: 24664 | H8: 17987 | I8: 32287 | J8: 24720 | K8: 31816 | L8: 57809 | M8: 47993 | N8: 18719
B9: OPM % | C9: 0.1491 | D9: 0.1406 | E9: 0.1097 | F9: 0.1079 | G9: 0.0817 | H9: 0.0689 | I9: 0.1293 | J9: 0.0888 | K9: 0.092 | L9: 0.1332 | M9: 0.1311 | N9: 0.0558
B10: Other Income | C10: 714 | D10: -2670 | E10: 1869 | F10: 5933 | G10: -26686 | H10: 102 | I10: -11118 | J10: 2424 | K10: 6664 | L10: 4807 | M10: 14219 | N10: 86291
B11: Interest | C11: 4861 | D11: 4889 | E11: 4238 | F11: 4682 | G11: 5759 | H11: 7243 | I11: 8097 | J11: 9312 | K11: 10225 | L11: 7594 | M11: 3901 | N11: 2827
B12: Depreciation | C12: 13389 | D12: 16711 | E12: 17905 | F12: 21554 | G12: 23591 | H12: 21425 | I12: 23547 | J12: 24836 | K12: 24860 | L12: 27239 | M12: 21102 | N12: 19784
B13: Profit Before Tax | C13: =C8+C10-C11-C12 -> 21703 | D13: =D8+D10-D11-D12 -> 14125 | E13: =E8+E10-E11-E12 -> 9315 | F13: =F8+F10-F11-F12 -> 11155 | G13: =G8+G10-G11-G12 -> -31372 | H13: =H8+H10-H11-H12 -> -10579 | I13: =I8+I10-I11-I12 -> -10475 | J13: =J8+J10-J11-J12 -> -7004 | ... N13: =N8+N10-N11-N12 -> 82399
B14: Tax % | C14: 0.35 | D14: 0.21 | E14: 0.35 | F14: 0.39 | G14: -0.08 | H14: 0.04 | I14: 0.24 | J14: 0.6 | K14: 0.21 | L14: -0.14 | M14: 0.24 | N14: 0
B15: Net Profit | C15: 14073 | D15: 11678 | E15: 7557 | F15: 9091 | G15: -28724 | H15: -11975 | I15: -13395 | J15: -11309 | K15: 2690 | L15: 31807 | M15: 28149 | N15: 82645
B16: EPS (₹) | C16: 48.44 | D16: 40.11 | E16: 25.82 | F16: 31.13 | G16: -99.84 | H16: -39.08 | I16: -40.51 | J16: -34.45 | K16: 7.27 | L16: 94.47 | M16: 75.6 | N16: 223.74
B18: BALANCE SHEET
C19: FY15 | D19: FY16 | E19: FY17 | F19: FY18 | G19: FY19 | H19: FY20 | I19: FY21 | J19: FY22 | K19: FY23 | L19: FY24 | M19: FY25 | N19: FY26
B20: Equity Capital | C20: 644 | D20: 679 | E20: 679 | F20: 679 | G20: 679 | H20: 720 | I20: 766 | J20: 766 | K20: 766 | L20: 767 | M20: 736 | N20: 737
B21: Reserves | C21: 55618 | D21: 78273 | E21: 57383 | F21: 94749 | G21: 59500 | H21: 62359 | I21: 54481 | J21: 43795 | K21: 44556 | L21: 84151 | M21: 115408 | N21: 111331
B22: Borrowings | C22: 73610 | D22: 69360 | E22: 78604 | F22: 88950 | G22: 106175 | H22: 124788 | I22: 142131 | J22: 146449 | K22: 134113 | L22: 107264 | M22: 71540 | N22: 79109
B23: Other Liabilities | C23: 107442 | D23: 114872 | E23: 135914 | F23: 142813 | G23: 139349 | H23: 132313 | I23: 144193 | J23: 138051 | K23: 155239 | L23: 177339 | M23: 189289 | N23: 188012
B24: Total Liabilities | C24: =SUM(C20:C23) -> 237314 | D24: =SUM(D20:D23) -> 263184 | E24: =SUM(E20:E23) -> 272580 | F24: =SUM(F20:F23) -> 327191 | G24: =SUM(G20:G23) -> 305703 | H24: =SUM(H20:H23) -> 320180 | I24: =SUM(I20:I23) -> 341571 | J24: =SUM(J20:J23) -> 329061 | ... N24: =SUM(N20:N23) -> 379189
B25: Fixed Assets | C25: 88479 | D25: 107232 | E25: 95944 | F25: 121414 | G25: 111234 | H25: 127107 | I25: 138708 | J25: 138855 | K25: 132080 | L25: 121285 | M25: 115697 | N25: 104656
B26: CWIP | C26: 28640 | D26: 25919 | E26: 33699 | F26: 40034 | G26: 31884 | H26: 35622 | I26: 20964 | J26: 10251 | K26: 14274 | L26: 35698 | M26: 65806 | N26: 102654
B27: Investments | C27: 15337 | D27: 23767 | E27: 20338 | F27: 20813 | G27: 15771 | H27: 16308 | I27: 24620 | J27: 29380 | K27: 26379 | L27: 22971 | M27: 35656 | N27: 26313
B28: Other Assets | C28: 104858 | D28: 106266 | E28: 122600 | F28: 144932 | G28: 146814 | H28: 141141 | I28: 157278 | J28: 150575 | K28: 161941 | L28: 189567 | M28: 159814 | N28: 145566
B29: Total Assets | C29: =SUM(C25:C28) -> 237314 | D29: =SUM(D25:D28) -> 263184 | E29: =SUM(E25:E28) -> 272581 | F29: =SUM(F25:F28) -> 327193 | G29: =SUM(G25:G28) -> 305703 | H29: =SUM(H25:H28) -> 320178 | I29: =SUM(I25:I28) -> 341570 | J29: =SUM(J25:J28) -> 329061 | ... N29: =SUM(N25:N28) -> 379189
B31: CASH FLOW
C32: FY15 | D32: FY16 | E32: FY17 | F32: FY18 | G32: FY19 | H32: FY20 | I32: FY21 | J32: FY22 | K32: FY23 | L32: FY24 | M32: FY25 | N32: FY26
B33: Cash from Operations | C33: 35531 | D33: 37900 | E33: 30199 | F33: 23857 | G33: 18891 | H33: 26633 | I33: 29001 | J33: 14283 | K33: 35388 | L33: 67915 | M33: 63102 | N33: 13041
B34: Cash from Investing | C34: -36232 | D34: -36694 | E34: -39571 | F34: -25139 | G34: -20878 | H34: -33115 | I34: -25672 | J34: -4444 | K34: -15417 | L34: -22781 | M34: -49982 | N34: -23166
B35: Cash from Financing | C35: 5201 | D35: -3795 | E35: 6205 | F35: 2012 | G35: 8830 | H35: 3390 | I35: 9904 | J35: -3380 | K35: -26243 | L35: -37006 | M35: -18786 | N35: -1344
B36: Net Cash Flow | C36: =SUM(C33:C35) -> 4500 | D36: =SUM(D33:D35) -> -2589 | E36: =SUM(E33:E35) -> -3167 | F36: =SUM(F33:F35) -> 730 | G36: =SUM(G33:G35) -> 6843 | H36: =SUM(H33:H35) -> -3092 | I36: =SUM(I33:I35) -> 13233 | J36: =SUM(J33:J35) -> 6459 | ... N36: =SUM(N33:N35) -> -11469
B38: EFFICIENCY RATIOS
C39: FY15 | D39: FY16 | E39: FY17 | F39: FY18 | G39: FY19 | H39: FY20 | I39: FY21 | J39: FY22 | K39: FY23 | L39: FY24 | M39: FY25 | N39: FY26
B40: ROCE % | C40: 0.21 | D40: 0.15 | E40: 0.09 | F40: 0.09 | G40: 0.02 | H40: 0 | I40: 0.06 | J40: 0.01 | K40: 0.06 | L40: 0.19 | M40: 0.16 | N40: 0.03
B41: Debtor Days | C41: 17 | D41: 18 | E41: 19 | F41: 25 | G41: 23 | H41: 16 | I41: 19 | J41: 16 | K41: 17 | L41: 14 | M41: 13 | N41: 14
B42: Inventory Days | C42: 67 | D42: 73 | E42: 77 | F42: 83 | G42: 73 | H42: 82 | I42: 83 | J42: 71 | K42: 66 | L42: 64 | M42: 78 | N42: 85
B43: Days Payable | C43: 131 | D43: 138 | E43: 138 | F43: 151 | G43: 133 | H43: 145 | I43: 175 | J43: 141 | K43: 128 | L43: 126 | M43: 160 | N43: 158
B44: Cash Conversion Cycle | C44: -47 | D44: -46 | E44: -41 | F44: -43 | G44: -38 | H44: -48 | I44: -74 | J44: -53 | K44: -45 | L44: -48 | M44: -69 | N44: -59
...

Sheet Assumptions
A1: ASSUMPTIONS & DRIVERS
B2: Blue cells = inputs. ₹ Cr unless stated. Year drivers in columns C–G apply to FY27E–FY31E.
B4: GLOBAL
B5: Risk-free rate (India 10Y G-sec) | C5: 0.065 | I5: RBI 10Y G-sec yield, Aug-2026
B6: Equity risk premium (India) | C6: 0.06 | I6: India equity risk premium (Damodaran-style), Aug-2026
B7: Valuation date | C7: 17-Aug-2026 | I7: CMP, market cap and net-debt anchors aligned to this date
B9: TMPV — TATA MOTORS PASSENGER VEHICLES
B10: Current market price (₹/share) | C10: 331 | I10: screener.in, 17-Aug-2026
B11: Shares outstanding (Cr) | C11: 368.5 | I11: Equity capital ₹737 Cr / FV ₹2
B12: Tax rate (forecast) | C12: 0.25
B13: Beta (levered) | C13: 1.15 | I13: JLR cyclicality + demerger uncertainty
B14: Pre-tax cost of debt | C14: 0.065 | I14: Assumed refinancing rate; FY26 implied cost on opening debt ~4-5%
B15: Terminal growth rate | C15: 0.03 | I15: Cut from 4% per analyst review — JLR-dominated cash flows, mature global market
B16: Cash & equivalents FY26 (₹ Cr) | C16: 22086 | I16: Derived: borrowings 79,109 − investments 26,313 − net debt 30,710
D18: FY27E | E18: FY28E | F18: FY29E | G18: FY30E | H18: FY31E
B19: Revenue growth % | D19: 0.12 | E19: 0.07 | F19: 0.06 | G19: 0.05 | H19: 0.05 | I19: FY27 = JLR post-cyberattack volume recovery + India PV growth — reconciled to segments in the cross-check below
B20: EBITDA margin % | D20: 0.095 | E20: 0.105 | F20: 0.11 | G20: 0.115 | H20: 0.12 | I20: Ramp: JLR mix (Range Rover/Defender) + India PV operating leverage; capped below FY25 restated peak of 13.1%
B21: Depreciation % of opening net PP&E | D21: 0.11 | E21: 0.11 | F21: 0.11 | G21: 0.11 | H21: 0.11 | I21: Linked to asset base: FY26 dep ₹19,784 Cr ≈ 11% of opening net PP&E
B22: Other income (₹ Cr, normalized) | D22: 2500 | E22: 2700 | F22: 2900 | G22: 3100 | H22: 3300 | I22: Trimmed (analyst review); excludes FY26 one-off ₹86,291 Cr
B23: Interest rate on opening borrowings | D23: 0.05 | E23: 0.05 | F23: 0.05 | G23: 0.05 | H23: 0.05 | I23: FY26 implied ~4-5% on opening debt
B24: Debt repayment — superseded by cash sweep | I24: Replaced by cash-sweep logic on the Debt Schedule (min-cash floor below)
B25: Capex % of revenue | D25: 0.09 | E25: 0.09 | F25: 0.08 | G25: 0.075 | H25: 0.075 | I25: Front-loaded EV capex, tapering (analyst review)
B26: Dividend payout % of PAT | D26: 0.15 | E26: 0.15 | F26: 0.15 | G26: 0.15 | H26: 0.15
B27: Receivable days (on revenue) | D27: 14 | E27: 14 | F27: 14 | G27: 14 | H27: 14 | I27: FY26: 14 days
B28: Inventory days (on operating costs) | D28: 90 | E28: 90 | F28: 90 | G28: 90 | H28: 90 | I28: FY26 anchor: inventory carve-out = 90.0 days of operating costs (was 85 days of revenue)
B29: Payable days (on operating costs) | D29: 167.3 | E29: 167.3 | F29: 167.3 | G29: 167.3 | H29: 167.3 | I29: FY26 anchor: payables carve-out = 167.3 days of operating costs (was 158 days of revenue)
B30: Other assets (residual) % of revenue | D30: 0.097 | E30: 0.097 | F30: 0.097 | G30: 0.097 | H30: 0.097 | I30: FY26 residual after receivables+inventory carve-out (₹32,459 Cr = 9.7%)
B31: Other liabilities (residual) % of revenue | D31: 0.127 | E31: 0.127 | F31: 0.127 | G31: 0.127 | H31: 0.127 | I31: FY26 residual after payables carve-out (₹42,758 Cr = 12.7%)
B32: Minimum operating cash (₹ Cr) | C32: 15000 | I32: Cash floor for the debt sweep (~4% of revenue); excess cash repays borrowings
B34: SEGMENT CROSS-CHECK — REVENUE (JLR vs INDIA PV)
B35: JLR revenue (₹ Cr) | C35: 261000 | D35: =C35*(1+D36) -> 297540 | E35: =D35*(1+E36) -> 319260.42 | F35: =E35*(1+F36) -> 338416.05 | G35: =F35*(1+G36) -> 355336.85 | H35: =G35*(1+H36) -> 373103.69 | I35: JLR FY26 revenue £22.9bn (FY26 results, May-2026) × ~₹114/£ ≈ ₹2,61,000 Cr — editable
B36: JLR revenue growth % | D36: 0.14 | E36: 0.073 | F36: 0.06 | G36: 0.05 | H36: 0.05
B37: India PV & other revenue (₹ Cr) | C37: ='Income Statement'!C4-C35 -> 74582 | D37: =C37*(1+D38) -> 78311.1 | E37: =D37*(1+E38) -> 83009.766 | F37: =E37*(1+F38) -> 87990.352 | G37: =F37*(1+G38) -> 92389.87 | H37: =G37*(1+H38) -> 97009.363
B38: India PV growth % | D38: 0.05 | E38: 0.06 | F38: 0.06 | G38: 0.05 | H38: 0.05
B39: Implied total revenue | C39: =C35+C37 -> 335582 | D39: =D35+D37 -> 375851.1 | E39: =E35+E37 -> 402270.19 | F39: =F35+F37 -> 426406.4 | G39: =G35+G37 -> 447726.72 | H39: =H35+H37 -> 470113.05
B40: Model consolidated revenue | C40: ='Income Statement'!C4 -> 335582 | D40: ='Income Statement'!D4 -> 375851.84 | E40: ='Income Statement'!E4 -> 402161.47 | F40: ='Income Statement'!F4 -> 426291.16 | G40: ='Income Statement'!G4 -> 447605.71 | H40: ='Income Statement'!H4 -> 469986
B41: Difference % (≈ 0 validates the consolidated growth path) | C41: =(C39-C40)/C40 -> 0 | D41: =(D39-D40)/D40 -> -1.9688609e-06 | E41: =(E39-E40)/E40 -> 0.00027033221 | F41: =(F39-F40)/F40 -> 0.00027033221 | G41: =(G39-G40)/G40 -> 0.00027033221 | H41: =(H39-H40)/H40 -> 0.00027033221 | I41: Turns the top-down growth assumption into segment operating paths (red-flags review #3). Tune JLR/India growth so the difference stays near 0.

Sheet Ratio Analysis
A1: RATIO ANALYSIS — FY26A & FORECAST (FY27E–FY31E)
B2: (All figures in ₹ Crores except per-share data)
C3: FY26A | D3: FY27E | E3: FY28E | F3: FY29E | G3: FY30E | H3: FY31E | I3: Trend | J3: How to read
B5: Profitability
B6: EBITDA margin % | C6: ='Income Statement'!C6/'Income Statement'!C4 -> 0.055780703 | D6: ='Income Statement'!D6/'Income Statement'!D4 -> 0.095 | E6: ='Income Statement'!E6/'Income Statement'!E4 -> 0.105 | F6: ='Income Statement'!F6/'Income Statement'!F4 -> 0.11 | G6: ='Income Statement'!G6/'Income Statement'!G4 -> 0.115 | H6: ='Income Statement'!H6/'Income Statement'!H4 -> 0.12 | J6: Operating profit per ₹1 of revenue — the core margin lever.
B7: EBIT margin % | C7: ='Income Statement'!C9/'Income Statement'!C4 -> -0.003173591 | D7: ='Income Statement'!D9/'Income Statement'!D4 -> 0.03432689 | E7: ='Income Statement'!E9/'Income Statement'!E4 -> 0.045281245 | F7: ='Income Statement'!F9/'Income Statement'!F4 -> 0.050519159 | G7: ='Income Statement'!G9/'Income Statement'!G4 -> 0.056201953 | H7: ='Income Statement'!H9/'Income Statement'!H4 -> 0.062304513 | J7: Margin after depreciation; what operations earn before funding costs.
B8: Net profit margin % | C8: ='Income Statement'!C14/'Income Statement'!C4 -> 0.24627364 | D8: ='Income Statement'!D14/'Income Statement'!D4 -> 0.022840865 | E8: ='Income Statement'!E14/'Income Statement'!E4 -> 0.032339868 | F8: ='Income Statement'!F14/'Income Statement'!F4 -> 0.036962469 | G8: ='Income Statement'!G14/'Income Statement'!G4 -> 0.042321532 | H8: ='Income Statement'!H14/'Income Statement'!H4 -> 0.048184154 | J8: PAT per ₹1 of revenue. FY26A inflated by the one-off demerger gain.
B9: Return on equity (ROE) % | C9: ='Income Statement'!C14/'Balance Sheet'!C12 -> 0.73745405 | D9: ='Income Statement'!D14/'Balance Sheet'!D12 -> 0.071920383 | E9: ='Income Statement'!E14/'Balance Sheet'!E12 -> 0.099722784 | F9: ='Income Statement'!F14/'Balance Sheet'!F12 -> 0.1095641 | G9: ='Income Statement'!G14/'Balance Sheet'!G12 -> 0.11845882 | H9: ='Income Statement'!H14/'Balance Sheet'!H12 -> 0.12639738 | J9: PAT / shareholders' funds — the owners' return.
B10: Return on capital employed (ROCE) % | C10: ='Income Statement'!C9/('Balance Sheet'!C12+'Balance Sheet'!C13) -> -0.0055707538 | D10: ='Income Statement'!D9/('Balance Sheet'!D12+'Balance Sheet'!D13) -> 0.0676374 | E10: ='Income Statement'!E9/('Balance Sheet'!E12+'Balance Sheet'!E13) -> 0.09152927 | F10: ='Income Statement'!F9/('Balance Sheet'!F12+'Balance Sheet'!F13) -> 0.10568023 | G10: ='Income Statement'!G9/('Balance Sheet'!G12+'Balance Sheet'!G13) -> 0.12113599 | H10: ='Income Statement'!H9/('Balance Sheet'!H12+'Balance Sheet'!H13) -> 0.13793321 | J10: EBIT / (equity + borrowings) — return on all long-term capital.
B11: Return on assets (ROA) % | C11: ='Income Statement'!C14/'Balance Sheet'!C9 -> 0.217952 | D11: ='Income Statement'!D14/'Balance Sheet'!D9 -> 0.021767182 | E11: ='Income Statement'!E14/'Balance Sheet'!E9 -> 0.031338676 | F11: ='Income Statement'!F14/'Balance Sheet'!F9 -> 0.036489026 | G11: ='Income Statement'!G14/'Balance Sheet'!G9 -> 0.042465799 | H11: ='Income Statement'!H14/'Balance Sheet'!H9 -> 0.049064668 | J11: PAT / total assets.
B13: Leverage & solvency
B14: Debt / equity (x) | C14: ='Balance Sheet'!C13/'Balance Sheet'!C12 -> 0.70590177 | D14: ='Balance Sheet'!D13/'Balance Sheet'!D12 -> 0.59803763 | E14: ='Balance Sheet'!E13/'Balance Sheet'!E12 -> 0.52550806 | F14: ='Balance Sheet'!F13/'Balance Sheet'!F12 -> 0.4169994 | G14: ='Balance Sheet'!G13/'Balance Sheet'!G12 -> 0.29862646 | H14: ='Balance Sheet'!H13/'Balance Sheet'!H12 -> 0.18490761 | J14: Borrowings vs owners' funds; <1x is comfortable.
B15: Net debt (₹ Cr) | C15: ='Balance Sheet'!C13-'Balance Sheet'!C8-'Balance Sheet'!C5 -> 30710 | D15: ='Balance Sheet'!D13-'Balance Sheet'!D8-'Balance Sheet'!D5 -> 30071.8 | E15: ='Balance Sheet'!E13-'Balance Sheet'!E8-'Balance Sheet'!E5 -> 27223.78 | F15: ='Balance Sheet'!F13-'Balance Sheet'!F8-'Balance Sheet'!F5 -> 18657.058 | G15: ='Balance Sheet'!G13-'Balance Sheet'!G8-'Balance Sheet'!G5 -> 6441.8956 | H15: ='Balance Sheet'!H13-'Balance Sheet'!H8-'Balance Sheet'!H5 -> -8184.1866 | J15: Borrowings − cash − investments. Negative = net cash. Matches company disclosure basis.
B16: Net debt / EBITDA (x) | C16: =('Balance Sheet'!C13-'Balance Sheet'!C8-'Balance Sheet'!C5)/'Income Statement'!C6 -> 1.6405791 | D16: =('Balance Sheet'!D13-'Balance Sheet'!D8-'Balance Sheet'!D5)/'Income Statement'!D6 -> 0.84220756 | E16: =('Balance Sheet'!E13-'Balance Sheet'!E8-'Balance Sheet'!E5)/'Income Statement'!E6 -> 0.64470148 | F16: =('Balance Sheet'!F13-'Balance Sheet'!F8-'Balance Sheet'!F5)/'Income Statement'!F6 -> 0.3978727 | G16: =('Balance Sheet'!G13-'Balance Sheet'!G8-'Balance Sheet'!G5)/'Income Statement'!G6 -> 0.12514693 | H16: =('Balance Sheet'!H13-'Balance Sheet'!H8-'Balance Sheet'!H5)/'Income Statement'!H6 -> -0.14511401 | J16: Years of EBITDA needed to repay net debt; <2x is safe, negative = net cash.
B17: Interest coverage (EBIT/interest, x) | C17: ='Income Statement'!C9/'Income Statement'!C11 -> -0.37672444 | D17: ='Income Statement'!D9/'Income Statement'!D11 -> 3.2617843 | E17: ='Income Statement'!E9/'Income Statement'!E11 -> 5.1020307 | F17: ='Income Statement'!F9/'Income Statement'!F11 -> 6.2844711 | G17: ='Income Statement'!G9/'Income Statement'!G11 -> 8.3896253 | H17: ='Income Statement'!H9/'Income Statement'!H11 -> 12.263559 | J17: How many times operating profit covers interest; >3x is comfortable.
B19: Efficiency
B20: Receivable days | C20: ='Balance Sheet'!C6/'Income Statement'!C4*365 -> 14.000393 | D20: ='Balance Sheet'!D6/'Income Statement'!D4*365 -> 14 | E20: ='Balance Sheet'!E6/'Income Statement'!E4*365 -> 14 | F20: ='Balance Sheet'!F6/'Income Statement'!F4*365 -> 14 | G20: ='Balance Sheet'!G6/'Income Statement'!G4*365 -> 14 | H20: ='Balance Sheet'!H6/'Income Statement'!H4*365 -> 14 | J20: Days of sales locked in receivables (assumption-driven).
B21: Fixed asset turnover (x) | C21: ='Income Statement'!C4/'Balance Sheet'!C4 -> 1.6187449 | D21: ='Income Statement'!D4/'Balance Sheet'!D4 -> 1.7214649 | E21: ='Income Statement'!E4/'Balance Sheet'!E4 -> 1.7446556 | F21: ='Income Statement'!F4/'Balance Sheet'!F4 -> 1.7817242 | G21: ='Income Statement'!G4/'Balance Sheet'!G4 -> 1.8157729 | H21: ='Income Statement'!H4/'Balance Sheet'!H4 -> 1.8456691 | J21: Revenue per ₹1 of net fixed assets.
B22: Total asset turnover (x) | C22: ='Income Statement'!C4/'Balance Sheet'!C9 -> 0.8849993 | D22: ='Income Statement'!D4/'Balance Sheet'!D9 -> 0.95299288 | E22: ='Income Statement'!E4/'Balance Sheet'!E9 -> 0.96904154 | F22: ='Income Statement'!F4/'Balance Sheet'!F9 -> 0.98719126 | G22: ='Income Statement'!G4/'Balance Sheet'!G9 -> 1.0034088 | H22: ='Income Statement'!H4/'Balance Sheet'!H9 -> 1.0182739 | J22: Revenue per ₹1 of total assets.
B23: Working capital days | C23: =('Balance Sheet'!C6+'Balance Sheet'!C7-'Balance Sheet'!C14)/'Income Statement'!C4*365 -> -70.189045 | D23: =('Balance Sheet'!D6+'Balance Sheet'!D7-'Balance Sheet'!D14)/'Income Statement'!D4*365 -> -66.9065 | E23: =('Balance Sheet'!E6+'Balance Sheet'!E7-'Balance Sheet'!E14)/'Income Statement'!E4*365 -> -66.1335 | F23: =('Balance Sheet'!F6+'Balance Sheet'!F7-'Balance Sheet'!F14)/'Income Statement'!F4*365 -> -65.747 | G23: =('Balance Sheet'!G6+'Balance Sheet'!G7-'Balance Sheet'!G14)/'Income Statement'!G4*365 -> -65.3605 | H23: =('Balance Sheet'!H6+'Balance Sheet'!H7-'Balance Sheet'!H14)/'Income Statement'!H4*365 -> -64.974 | J23: Negative = suppliers/customers fund operations (auto-OEM norm).
B26: Per-share & valuation (at current market price)
B27: EPS (₹) | C27: ='Income Statement'!C15 -> 224.27408 | D27: ='Income Statement'!D15 -> 23.296557 | E27: ='Income Statement'!E15 -> 35.294027 | F27: ='Income Statement'!F15 -> 42.759223 | G27: ='Income Statement'!G15 -> 51.406674 | H27: ='Income Statement'!H15 -> 61.454215 | J27: PAT / shares outstanding.
B28: Book value per share (₹) | C28: ='Balance Sheet'!C12/Assumptions!$C$11 -> 304.1194 | D28: ='Balance Sheet'!D12/Assumptions!$C$11 -> 323.92148 | E28: ='Balance Sheet'!E12/Assumptions!$C$11 -> 353.9214 | F28: ='Balance Sheet'!F12/Assumptions!$C$11 -> 390.26674 | G28: ='Balance Sheet'!G12/Assumptions!$C$11 -> 433.96241 | H28: ='Balance Sheet'!H12/Assumptions!$C$11 -> 486.19849 | J28: Equity / shares.
B29: Dividend per share (₹) | C29: ='Income Statement'!C16/Assumptions!$C$11 -> 2.9986431 | D29: ='Income Statement'!D16/Assumptions!$C$11 -> 3.4944835 | E29: ='Income Statement'!E16/Assumptions!$C$11 -> 5.2941041 | F29: ='Income Statement'!F16/Assumptions!$C$11 -> 6.4138834 | G29: ='Income Statement'!G16/Assumptions!$C$11 -> 7.7110012 | H29: ='Income Statement'!H16/Assumptions!$C$11 -> 9.2181322
B30: Dividend payout % | C30: ='Income Statement'!C16/'Income Statement'!C14 -> 0.01337044 | D30: ='Income Statement'!D16/'Income Statement'!D14 -> 0.15 | E30: ='Income Statement'!E16/'Income Statement'!E14 -> 0.15 | F30: ='Income Statement'!F16/'Income Statement'!F14 -> 0.15 | G30: ='Income Statement'!G16/'Income Statement'!G14 -> 0.15 | H30: ='Income Statement'!H16/'Income Statement'!H14 -> 0.15 | J30: Share of PAT returned to shareholders.
B31: P/E (x) | C31: =Assumptions!$C$10/'Income Statement'!C15 -> 1.4758727 | D31: =Assumptions!$C$10/'Income Statement'!D15 -> 14.208108 | E31: =Assumptions!$C$10/'Income Statement'!E15 -> 9.3783574 | F31: =Assumptions!$C$10/'Income Statement'!F15 -> 7.74102 | G31: =Assumptions!$C$10/'Income Statement'!G15 -> 6.4388526 | H31: =Assumptions!$C$10/'Income Statement'!H15 -> 5.3861237 | J31: Price vs earnings: falling forward P/E on a flat price = earnings growth.
B32: P/B (x) | C32: =Assumptions!$C$10/('Balance Sheet'!C12/Assumptions!$C$11) -> 1.0883883 | D32: =Assumptions!$C$10/('Balance Sheet'!D12/Assumptions!$C$11) -> 1.0218526 | E32: =Assumptions!$C$10/('Balance Sheet'!E12/Assumptions!$C$11) -> 0.9352359 | F32: =Assumptions!$C$10/('Balance Sheet'!F12/Assumptions!$C$11) -> 0.84813787 | G32: =Assumptions!$C$10/('Balance Sheet'!G12/Assumptions!$C$11) -> 0.76273887 | H32: =Assumptions!$C$10/('Balance Sheet'!H12/Assumptions!$C$11) -> 0.68079191 | J32: Price vs book value.
B33: EV / EBITDA (x) | C33: =(Assumptions!$C$10*Assumptions!$C$11+'Balance Sheet'!C13-'Balance Sheet'!C8-'Balance Sheet'!C5)/'Income Statement'!C6 -> 8.1566056 | D33: =(Assumptions!$C$10*Assumptions!$C$11+'Balance Sheet'!D13-'Balance Sheet'!D8-'Balance Sheet'!D5)/'Income Statement'!D6 -> 4.2582653 | E33: =(Assumptions!$C$10*Assumptions!$C$11+'Balance Sheet'!E13-'Balance Sheet'!E8-'Balance Sheet'!E5)/'Income Statement'!E6 -> 3.5332238 | F33: =(Assumptions!$C$10*Assumptions!$C$11+'Balance Sheet'!F13-'Balance Sheet'!F8-'Balance Sheet'!F5)/'Income Statement'!F6 -> 2.9990292 | G33: =(Assumptions!$C$10*Assumptions!$C$11+'Balance Sheet'!G13-'Balance Sheet'!G8-'Balance Sheet'!G5)/'Income Statement'!G6 -> 2.4947305 | H33: =(Assumptions!$C$10*Assumptions!$C$11+'Balance Sheet'!H13-'Balance Sheet'!H8-'Balance Sheet'!H5)/'Income Statement'!H6 -> 2.0176011 | J33: Capital-structure-neutral valuation multiple.
B36: Growth
B37: Revenue growth % | C37: n.m. | D37: ='Income Statement'!D5 -> 0.12 | E37: ='Income Statement'!E5 -> 0.07 | F37: ='Income Statement'!F5 -> 0.06 | G37: ='Income Statement'!G5 -> 0.05 | H37: ='Income Statement'!H5 -> 0.05
B38: PAT growth % | C38: n.m. | D38: ='Income Statement'!D14/'Income Statement'!C14-1 -> -0.89612462 | E38: ='Income Statement'!E14/'Income Statement'!D14-1 -> 0.51498901 | F38: ='Income Statement'!F14/'Income Statement'!E14-1 -> 0.21151442 | G38: ='Income Statement'!G14/'Income Statement'!F14-1 -> 0.20223593 | H38: ='Income Statement'!H14/'Income Statement'!G14-1 -> 0.19545206 | J38: FY27E vs FY26A is not meaningful where FY26 PAT carries one-offs.
B40: Note: FY26A interest coverage / ROE / NPM are distorted (one-off demerger gain; cyberattack-hit EBIT). Historical screener ratios are on the TMPV Historical tab.

Sheet Working Capital Schedule
A1: TMPV — WORKING CAPITAL SCHEDULE (₹ Cr)
B2: (All figures in ₹ Crores except per-share data)
C3: FY26A | D3: FY27E | E3: FY28E | F3: FY29E | G3: FY30E | H3: FY31E
B4: DRIVERS
B5: Revenue | C5: ='Income Statement'!C4 -> 335582 | D5: ='Income Statement'!D4 -> 375851.84 | E5: ='Income Statement'!E4 -> 402161.47 | F5: ='Income Statement'!F4 -> 426291.16 | G5: ='Income Statement'!G4 -> 447605.71 | H5: ='Income Statement'!H4 -> 469986
B6: Operating costs (revenue − EBITDA) | C6: ='Income Statement'!C4-'Income Statement'!C6 -> 316863 | D6: ='Income Statement'!D4-'Income Statement'!D6 -> 340145.92 | E6: ='Income Statement'!E4-'Income Statement'!E6 -> 359934.51 | F6: ='Income Statement'!F4-'Income Statement'!F6 -> 379399.13 | G6: ='Income Statement'!G4-'Income Statement'!G6 -> 396131.06 | H6: ='Income Statement'!H4-'Income Statement'!H6 -> 413587.68
B7: Receivable days (on revenue) | C7: =C14/C5*365 -> 14.000393 | D7: =Assumptions!D27 -> 14 | E7: =Assumptions!E27 -> 14 | F7: =Assumptions!F27 -> 14 | G7: =Assumptions!G27 -> 14 | H7: =Assumptions!H27 -> 14
B8: Inventory days (on operating costs) | C8: =C15/C6*365 -> 90.02146 | D8: =Assumptions!D28 -> 90 | E8: =Assumptions!E28 -> 90 | F8: =Assumptions!F28 -> 90 | G8: =Assumptions!G28 -> 90 | H8: =Assumptions!H28 -> 90
B9: Payable days (on operating costs) | C9: =C17/C6*365 -> 167.33401 | D9: =Assumptions!D29 -> 167.3 | E9: =Assumptions!E29 -> 167.3 | F9: =Assumptions!F29 -> 167.3 | G9: =Assumptions!G29 -> 167.3 | H9: =Assumptions!H29 -> 167.3
B10: Other assets (residual) % of revenue | C10: =C16/C5 -> 0.096723803 | D10: =Assumptions!D30 -> 0.097 | E10: =Assumptions!E30 -> 0.097 | F10: =Assumptions!F30 -> 0.097 | G10: =Assumptions!G30 -> 0.097 | H10: =Assumptions!H30 -> 0.097
B11: Other liabilities (residual) % of revenue | C11: =C18/C5 -> 0.1273798 | D11: =Assumptions!D31 -> 0.127 | E11: =Assumptions!E31 -> 0.127 | F11: =Assumptions!F31 -> 0.127 | G11: =Assumptions!G31 -> 0.127 | H11: =Assumptions!H31 -> 0.127
B13: WORKING CAPITAL BALANCES
B14: Receivables | C14: ='Balance Sheet'!C6 -> 12872 | D14: =D5*D7/365 -> 14416.235 | E14: =E5*E7/365 -> 15425.371 | F14: =F5*F7/365 -> 16350.894 | G14: =G5*G7/365 -> 17168.438 | H14: =H5*H7/365 -> 18026.86
B15: Inventory | C15: =C5*85/365 -> 78149.233 | D15: =D6*D8/365 -> 83871.596 | E15: =E6*E8/365 -> 88750.976 | F15: =F6*F8/365 -> 93550.47 | G15: =G6*G8/365 -> 97676.151 | H15: =H6*H8/365 -> 101980.52
B16: Other assets (residual) | C16: ='Balance Sheet'!C7-C15 -> 32458.767 | D16: =D5*D10 -> 36457.628 | E16: =E5*E10 -> 39009.662 | F16: =F5*F10 -> 41350.242 | G16: =G5*G10 -> 43417.754 | H16: =H5*H10 -> 45588.642
B17: Payables | C17: =C5*158/365 -> 145265.63 | D17: =D6*D9/365 -> 155907.98 | E17: =E6*E9/365 -> 164978.2 | F17: =F6*F9/365 -> 173899.93 | G17: =G6*G9/365 -> 181569.11 | H17: =H6*H9/365 -> 189570.46
B18: Other liabilities (residual) | C18: ='Balance Sheet'!C14-C17 -> 42746.367 | D18: =D5*D11 -> 47733.184 | E18: =E5*E11 -> 51074.507 | F18: =F5*F11 -> 54138.977 | G18: =G5*G11 -> 56845.926 | H18: =H5*H11 -> 59688.222
B19: Net working capital | C19: =C14+C15+C16-C17-C18 -> -64532 | D19: =D14+D15+D16-D17-D18 -> -68895.702 | E19: =E14+E15+E16-E17-E18 -> -72866.7 | F19: =F14+F15+F16-F17-F18 -> -76787.301 | G19: =G14+G15+G16-G17-G18 -> -80152.694 | H19: =H14+H15+H16-H17-H18 -> -83662.659
B21: CHANGE IN WORKING CAPITAL
B22: Increase / (decrease) in NWC | C22: n.a. | D22: =D19-C19 -> -4363.7017 | E22: =E19-D19 -> -3970.9983 | F22: =F19-E19 -> -3920.6005 | G22: =G19-F19 -> -3365.3935 | H22: =H19-G19 -> -3509.9646
B24: Inventory and payable days are driven off operating costs (revenue − EBITDA), the economically relevant base (analyst red-flags review, Aug-2026). FY26 balances are unchanged: the screener carve-out (85/158 days of revenue) equals 90.0/167.3 days of operating costs.
B25: Negative NWC (supplier credit + customer advances funding operations) is the auto-OEM norm. The deepening trend is a ratio-extrapolation assumption — monitor supplier terms, mix and financing arrangements.

Sheet Dep & Capex Schedule
A1: TMPV — DEPRECIATION & CAPEX SCHEDULE (₹ Cr)
B2: (All figures in ₹ Crores except per-share data)
C3: FY26A | D3: FY27E | E3: FY28E | F3: FY29E | G3: FY30E | H3: FY31E
B5: Revenue | C5: ='Income Statement'!C4 -> 335582 | D5: ='Income Statement'!D4 -> 375851.84 | E5: ='Income Statement'!E4 -> 402161.47 | F5: ='Income Statement'!F4 -> 426291.16 | G5: ='Income Statement'!G4 -> 447605.71 | H5: ='Income Statement'!H4 -> 469986
B6: Capex % of revenue | D6: =Assumptions!D25 -> 0.09 | E6: =Assumptions!E25 -> 0.09 | F6: =Assumptions!F25 -> 0.08 | G6: =Assumptions!G25 -> 0.075 | H6: =Assumptions!H25 -> 0.075
B7: Depreciation % of opening net PP&E | C7: n.a. | D7: =Assumptions!D21 -> 0.11 | E7: =Assumptions!E21 -> 0.11 | F7: =Assumptions!F21 -> 0.11 | G7: =Assumptions!G21 -> 0.11 | H7: =Assumptions!H21 -> 0.11
B9: DEPRECIATION
B10: Depreciation | C10: ='Income Statement'!C8 -> 19784 | D10: =D13*D7 -> 22804.1 | E10: =E13*E7 -> 24016.582 | F10: =F13*F7 -> 25356.157 | G10: =G13*G7 -> 26318.342 | H10: =H13*H7 -> 27116.071
B12: NET PP&E ROLL-FORWARD (INCL. CWIP)
B13: Beginning Net PP&E | D13: ='Balance Sheet'!C4 -> 207310 | E13: =D16 -> 218332.57 | F13: =E16 -> 230510.52 | G13: =F16 -> 239257.65 | H13: =G16 -> 246509.74
B14: + Capital expenditure | D14: =D5*D6 -> 33826.666 | E14: =E5*E6 -> 36194.532 | F14: =F5*F6 -> 34103.293 | G14: =G5*G6 -> 33570.429 | H14: =H5*H6 -> 35248.95
B15: − Depreciation | D15: =-D10 -> -22804.1 | E15: =-E10 -> -24016.582 | F15: =-F10 -> -25356.157 | G15: =-G10 -> -26318.342 | H15: =-H10 -> -27116.071
B16: Ending Net PP&E | C16: ='Balance Sheet'!C4 -> 207310 | D16: =SUM(D13:D15) -> 218332.57 | E16: =SUM(E13:E15) -> 230510.52 | F16: =SUM(F13:F15) -> 239257.65 | G16: =SUM(G13:G15) -> 246509.74 | H16: =SUM(H13:H15) -> 254642.62
B18: Feeds the Model: 'Depreciation' (P&L) and 'Net fixed assets' (BS). Depreciation is driven by opening net PP&E (asset base), not revenue.

Sheet Debt Schedule
A1: TMPV — DEBT & INTEREST SCHEDULE (₹ Cr)
B2: (All figures in ₹ Crores except per-share data)
C3: FY26A | D3: FY27E | E3: FY28E | F3: FY29E | G3: FY30E | H3: FY31E
B4: BORROWINGS ROLL-FORWARD
B5: Beginning balance | C5: n.a. | D5: ='Balance Sheet'!C13 -> 79109 | E5: =D8 -> 71384.8 | F5: =E8 -> 68536.78 | G5: =F8 -> 59970.058 | H5: =G8 -> 47754.896
B6: + New borrowings (auto-revolver, discretionary) | C6: n.a. | D6: =MAX(0,Assumptions!$C$32-('Cash Flow'!D16+'Cash Flow'!D9+'Cash Flow'!D11+'Cash Flow'!D13)) -> 0 | E6: =MAX(0,Assumptions!$C$32-('Cash Flow'!E16+'Cash Flow'!E9+'Cash Flow'!E11+'Cash Flow'!E13)) -> 0 | F6: =MAX(0,Assumptions!$C$32-('Cash Flow'!F16+'Cash Flow'!F9+'Cash Flow'!F11+'Cash Flow'!F13)) -> 0 | G6: =MAX(0,Assumptions!$C$32-('Cash Flow'!G16+'Cash Flow'!G9+'Cash Flow'!G11+'Cash Flow'!G13)) -> 0 | H6: =MAX(0,Assumptions!$C$32-('Cash Flow'!H16+'Cash Flow'!H9+'Cash Flow'!H11+'Cash Flow'!H13)) -> 0
B7: − Repayment (discretionary cash sweep) | C7: n.a. | D7: =-MIN(D5,MAX(0,'Cash Flow'!D16+'Cash Flow'!D9+'Cash Flow'!D11+'Cash Flow'!D13-Assumptions!$C$32)) -> -7724.2001 | E7: =-MIN(E5,MAX(0,'Cash Flow'!E16+'Cash Flow'!E9+'Cash Flow'!E11+'Cash Flow'!E13-Assumptions!$C$32)) -> -2848.0199 | F7: =-MIN(F5,MAX(0,'Cash Flow'!F16+'Cash Flow'!F9+'Cash Flow'!F11+'Cash Flow'!F13-Assumptions!$C$32)) -> -8566.7223 | G7: =-MIN(G5,MAX(0,'Cash Flow'!G16+'Cash Flow'!G9+'Cash Flow'!G11+'Cash Flow'!G13-Assumptions!$C$32)) -> -12215.162 | H7: =-MIN(H5,MAX(0,'Cash Flow'!H16+'Cash Flow'!H9+'Cash Flow'!H11+'Cash Flow'!H13-Assumptions!$C$32)) -> -14626.082
B8: Ending balance | C8: ='Balance Sheet'!C13 -> 79109 | D8: =SUM(D5:D7) -> 71384.8 | E8: =SUM(E5:E7) -> 68536.78 | F8: =SUM(F5:F7) -> 59970.058 | G8: =SUM(G5:G7) -> 47754.896 | H8: =SUM(H5:H7) -> 33128.813
B10: INTEREST EXPENSE
B11: Interest rate on opening borrowings | C11: n.a. | D11: =Assumptions!D23 -> 0.05 | E11: =Assumptions!E23 -> 0.05 | F11: =Assumptions!F23 -> 0.05 | G11: =Assumptions!G23 -> 0.05 | H11: =Assumptions!H23 -> 0.05
B12: Interest expense | C12: ='Income Statement'!C11 -> 2827 | D12: =D5*D11 -> 3955.45 | E12: =E5*E11 -> 3569.24 | F12: =F5*F11 -> 3426.839 | G12: =G5*G11 -> 2998.5029 | H12: =H5*H11 -> 2387.7448
B14: Cash sweep: all cash above the minimum-cash floor (Assumptions) repays debt each year. No circularity — interest accrues on OPENING debt and the sweep uses same-year pre-financing cash flows.
B15: Issuance is an automatic revolver — if pre-financing cash falls below the minimum-cash floor, debt is issued to restore the floor. Interest income sits inside 'Other income'.
B16: Feeds the Model: 'Interest expense' (P&L) and 'Borrowings' (BS).
B17: No contractual amortization/maturity ladder is modeled — TMPV's post-demerger maturity schedule is not disclosed in the data source; all repayment is the discretionary sweep (red-flags review #10).
B18: Interest is charged on OPENING borrowings to avoid circularity. In a deleveraging forecast this slightly overstates interest — a conservative simplification (red-flags review #5).

Sheet Income Statement
A1: INCOME STATEMENT | C1: Actual | D1: Forecasts
B2: (All figures in ₹ Crores except per-share data) | C2: FY26A | D2: FY27E | E2: FY28E | F2: FY29E | G2: FY30E | H2: FY31E
B4: Revenue | C4: 335582 | D4: =C4*(1+Assumptions!D19) -> 375851.84 | E4: =D4*(1+Assumptions!E19) -> 402161.47 | F4: =E4*(1+Assumptions!F19) -> 426291.16 | G4: =F4*(1+Assumptions!G19) -> 447605.71 | H4: =G4*(1+Assumptions!H19) -> 469986
B5: Growth % | D5: =D4/C4-1 -> 0.12 | E5: =E4/D4-1 -> 0.07 | F5: =F4/E4-1 -> 0.06 | G5: =G4/F4-1 -> 0.05 | H5: =H4/G4-1 -> 0.05
B6: EBITDA (Operating Profit) | C6: 18719 | D6: =D4*Assumptions!D20 -> 35705.925 | E6: =E4*Assumptions!E20 -> 42226.954 | F6: =F4*Assumptions!F20 -> 46892.027 | G6: =G4*Assumptions!G20 -> 51474.657 | H6: =H4*Assumptions!H20 -> 56398.32
B7: EBITDA margin % | D7: =D6/D4 -> 0.095 | E7: =E6/E4 -> 0.105 | F7: =F6/F4 -> 0.11 | G7: =G6/G4 -> 0.115 | H7: =H6/H4 -> 0.12
B8: Depreciation | C8: 19784 | D8: ='Dep & Capex Schedule'!D10 -> 22804.1 | E8: ='Dep & Capex Schedule'!E10 -> 24016.582 | F8: ='Dep & Capex Schedule'!F10 -> 25356.157 | G8: ='Dep & Capex Schedule'!G10 -> 26318.342 | H8: ='Dep & Capex Schedule'!H10 -> 27116.071
B9: EBIT | C9: =C6-C8 -> -1065 | D9: =D6-D8 -> 12901.825 | E9: =E6-E8 -> 18210.372 | F9: =F6-F8 -> 21535.871 | G9: =G6-G8 -> 25156.316 | H9: =H6-H8 -> 29282.249
B10: Other income | C10: 86291 | D10: =Assumptions!D22 -> 2500 | E10: =Assumptions!E22 -> 2700 | F10: =Assumptions!F22 -> 2900 | G10: =Assumptions!G22 -> 3100 | H10: =Assumptions!H22 -> 3300
B11: Interest expense | C11: 2827 | D11: ='Debt Schedule'!D12 -> 3955.45 | E11: ='Debt Schedule'!E12 -> 3569.24 | F11: ='Debt Schedule'!F12 -> 3426.839 | G11: ='Debt Schedule'!G12 -> 2998.5029 | H11: ='Debt Schedule'!H12 -> 2387.7448
B12: Profit before tax | C12: =C9+C10-C11 -> 82399 | D12: =D9+D10-D11 -> 11446.375 | E12: =E9+E10-E11 -> 17341.132 | F12: =F9+F10-F11 -> 21009.032 | G12: =G9+G10-G11 -> 25257.813 | H12: =H9+H10-H11 -> 30194.504
B13: Tax | C13: -246 | D13: =D12*Assumptions!$C$12 -> 2861.5937 | E13: =E12*Assumptions!$C$12 -> 4335.283 | F13: =F12*Assumptions!$C$12 -> 5252.2579 | G13: =G12*Assumptions!$C$12 -> 6314.4532 | H13: =H12*Assumptions!$C$12 -> 7548.626
B14: PAT | C14: =C12-C13 -> 82645 | D14: =D12-D13 -> 8584.7811 | E14: =E12-E13 -> 13005.849 | F14: =F12-F13 -> 15756.774 | G14: =G12-G13 -> 18943.359 | H14: =H12-H13 -> 22645.878
B15: EPS (₹) | C15: =C14/Assumptions!$C$11 -> 224.27408 | D15: =D14/Assumptions!$C$11 -> 23.296557 | E15: =E14/Assumptions!$C$11 -> 35.294027 | F15: =F14/Assumptions!$C$11 -> 42.759223 | G15: =G14/Assumptions!$C$11 -> 51.406674 | H15: =H14/Assumptions!$C$11 -> 61.454215
B16: Dividends paid | C16: 1105 | D16: =D14*Assumptions!D26 -> 1287.7172 | E16: =E14*Assumptions!E26 -> 1950.8774 | F16: =F14*Assumptions!F26 -> 2363.516 | G16: =G14*Assumptions!G26 -> 2841.5039 | H16: =H14*Assumptions!H26 -> 3396.8817
B18: FY26A as reported (restated PV+JLR). FY26 other income contains a ₹86,291 Cr one-off demerger gain;
B19: forecasts use normalized other income from Assumptions. FY26 dividends estimated from 0.91% yield.
B21: FY26 REPORTED → NORMALIZED EARNINGS BRIDGE
B22: Reported PBT (FY26A) | C22: =C12 -> 82399
B23: Less: one-off demerger gain in other income | C23: -86291
B24: Normalized PBT (FY26A) | C24: =C22+C23 -> -3892
B25: Less: tax as reported (one-off gain is non-taxable) | C25: =C13 -> -246
B26: Normalized PAT (FY26A) | C26: =C24-C25 -> -3646
B27: The FY27E PAT rebuild starts from this cyberattack-depressed normalized base — not an operational collapse from reported ₹82,645 Cr (red-flags review #4).

Sheet Balance Sheet
A1: BALANCE SHEET | C1: Actual | D1: Forecasts
B2: (All figures in ₹ Crores except per-share data) | C2: FY26A | D2: FY27E | E2: FY28E | F2: FY29E | G2: FY30E | H2: FY31E
B4: Net fixed assets (incl. CWIP) | C4: 207310 | D4: ='Dep & Capex Schedule'!D16 -> 218332.57 | E4: ='Dep & Capex Schedule'!E16 -> 230510.52 | F4: ='Dep & Capex Schedule'!F16 -> 239257.65 | G4: ='Dep & Capex Schedule'!G16 -> 246509.74 | H4: ='Dep & Capex Schedule'!H16 -> 254642.62
B5: Investments | C5: 26313 | D5: =C5 -> 26313 | E5: =D5 -> 26313 | F5: =E5 -> 26313 | G5: =F5 -> 26313 | H5: =G5 -> 26313
B6: Receivables | C6: 12872 | D6: ='Working Capital Schedule'!D14 -> 14416.235 | E6: ='Working Capital Schedule'!E14 -> 15425.371 | F6: ='Working Capital Schedule'!F14 -> 16350.894 | G6: ='Working Capital Schedule'!G14 -> 17168.438 | H6: ='Working Capital Schedule'!H14 -> 18026.86
B7: Other assets (incl. inventory) | C7: 110608 | D7: ='Working Capital Schedule'!D15+'Working Capital Schedule'!D16 -> 120329.22 | E7: ='Working Capital Schedule'!E15+'Working Capital Schedule'!E16 -> 127760.64 | F7: ='Working Capital Schedule'!F15+'Working Capital Schedule'!F16 -> 134900.71 | G7: ='Working Capital Schedule'!G15+'Working Capital Schedule'!G16 -> 141093.91 | H7: ='Working Capital Schedule'!H15+'Working Capital Schedule'!H16 -> 147569.17
B8: Cash & equivalents | C8: =Assumptions!$C$16 -> 22086 | D8: ='Cash Flow'!D17 -> 15000 | E8: ='Cash Flow'!E17 -> 15000 | F8: ='Cash Flow'!F17 -> 15000 | G8: ='Cash Flow'!G17 -> 15000 | H8: ='Cash Flow'!H17 -> 15000
B9: TOTAL ASSETS | C9: =SUM(C4:C8) -> 379189 | D9: =SUM(D4:D8) -> 394391.02 | E9: =SUM(E4:E8) -> 415009.53 | F9: =SUM(F4:F8) -> 431822.26 | G9: =SUM(G4:G8) -> 446085.08 | H9: =SUM(H4:H8) -> 461551.64
B10: Equity share capital | C10: 737 | D10: =C10 -> 737 | E10: =D10 -> 737 | F10: =E10 -> 737 | G10: =F10 -> 737 | H10: =G10 -> 737
B11: Reserves | C11: 111331 | D11: =C11+'Income Statement'!D14-'Income Statement'!D16 -> 118628.06 | E11: =D11+'Income Statement'!E14-'Income Statement'!E16 -> 129683.04 | F11: =E11+'Income Statement'!F14-'Income Statement'!F16 -> 143076.29 | G11: =F11+'Income Statement'!G14-'Income Statement'!G16 -> 159178.15 | H11: =G11+'Income Statement'!H14-'Income Statement'!H16 -> 178427.15
B12: Total equity | C12: =C10+C11 -> 112068 | D12: =D10+D11 -> 119365.06 | E12: =E10+E11 -> 130420.04 | F12: =F10+F11 -> 143813.29 | G12: =G10+G11 -> 159915.15 | H12: =H10+H11 -> 179164.15
B13: Borrowings | C13: 79109 | D13: ='Debt Schedule'!D8 -> 71384.8 | E13: ='Debt Schedule'!E8 -> 68536.78 | F13: ='Debt Schedule'!F8 -> 59970.058 | G13: ='Debt Schedule'!G8 -> 47754.896 | H13: ='Debt Schedule'!H8 -> 33128.813
B14: Other liabilities (incl. payables) | C14: 188012 | D14: ='Working Capital Schedule'!D17+'Working Capital Schedule'!D18 -> 203641.16 | E14: ='Working Capital Schedule'!E17+'Working Capital Schedule'!E18 -> 216052.71 | F14: ='Working Capital Schedule'!F17+'Working Capital Schedule'!F18 -> 228038.91 | G14: ='Working Capital Schedule'!G17+'Working Capital Schedule'!G18 -> 238415.04 | H14: ='Working Capital Schedule'!H17+'Working Capital Schedule'!H18 -> 249258.68
B15: TOTAL EQUITY & LIABILITIES | C15: =C12+C13+C14 -> 379189 | D15: =D12+D13+D14 -> 394391.02 | E15: =E12+E13+E14 -> 415009.53 | F15: =F12+F13+F14 -> 431822.26 | G15: =G12+G13+G14 -> 446085.08 | H15: =H12+H13+H14 -> 461551.64
B16: Balance check (must be 0) | C16: =C9-C15 -> 0 | D16: =D9-D15 -> 0 | E16: =E9-E15 -> 0 | F16: =F9-F15 -> 0 | G16: =G9-G15 -> 0 | H16: =H9-H15 -> 0

Sheet Cash Flow
A1: CASH FLOW STATEMENT | C1: Actual | D1: Forecasts
B2: (All figures in ₹ Crores except per-share data) | C2: FY26A | D2: FY27E | E2: FY28E | F2: FY29E | G2: FY30E | H2: FY31E
B4: PAT | D4: ='Income Statement'!D14 -> 8584.7811 | E4: ='Income Statement'!E14 -> 13005.849 | F4: ='Income Statement'!F14 -> 15756.774 | G4: ='Income Statement'!G14 -> 18943.359 | H4: ='Income Statement'!H14 -> 22645.878
B5: + Depreciation | D5: ='Income Statement'!D8 -> 22804.1 | E5: ='Income Statement'!E8 -> 24016.582 | F5: ='Income Statement'!F8 -> 25356.157 | G5: ='Income Statement'!G8 -> 26318.342 | H5: ='Income Statement'!H8 -> 27116.071
B6: − Increase in receivables | D6: =-('Balance Sheet'!D6-'Balance Sheet'!C6) -> -1544.235 | E6: =-('Balance Sheet'!E6-'Balance Sheet'!D6) -> -1009.1364 | F6: =-('Balance Sheet'!F6-'Balance Sheet'!E6) -> -925.52228 | G6: =-('Balance Sheet'!G6-'Balance Sheet'!F6) -> -817.54468 | H6: =-('Balance Sheet'!H6-'Balance Sheet'!G6) -> -858.42192
B7: − Increase in other assets | D7: =-('Balance Sheet'!D7-'Balance Sheet'!C7) -> -9721.224 | E7: =-('Balance Sheet'!E7-'Balance Sheet'!D7) -> -7431.4147 | F7: =-('Balance Sheet'!F7-'Balance Sheet'!E7) -> -7140.0739 | G7: =-('Balance Sheet'!G7-'Balance Sheet'!F7) -> -6193.193 | H7: =-('Balance Sheet'!H7-'Balance Sheet'!G7) -> -6475.2605
B8: + Increase in other liabilities | D8: ='Balance Sheet'!D14-'Balance Sheet'!C14 -> 15629.161 | E8: ='Balance Sheet'!E14-'Balance Sheet'!D14 -> 12411.549 | F8: ='Balance Sheet'!F14-'Balance Sheet'!E14 -> 11986.197 | G8: ='Balance Sheet'!G14-'Balance Sheet'!F14 -> 10376.131 | H8: ='Balance Sheet'!H14-'Balance Sheet'!G14 -> 10843.647
B9: Cash from operations | D9: =SUM(D4:D8) -> 35752.583 | E9: =SUM(E4:E8) -> 40993.429 | F9: =SUM(F4:F8) -> 45033.531 | G9: =SUM(G4:G8) -> 48627.095 | H9: =SUM(H4:H8) -> 53271.914
B10: − Capex | D10: =-'Dep & Capex Schedule'!D14 -> -33826.666 | E10: =-'Dep & Capex Schedule'!E14 -> -36194.532 | F10: =-'Dep & Capex Schedule'!F14 -> -34103.293 | G10: =-'Dep & Capex Schedule'!G14 -> -33570.429 | H10: =-'Dep & Capex Schedule'!H14 -> -35248.95
B11: Cash from investing | D11: =D10 -> -33826.666 | E11: =E10 -> -36194.532 | F11: =F10 -> -34103.293 | G11: =G10 -> -33570.429 | H11: =H10 -> -35248.95
B12: − Debt repayment | D12: ='Balance Sheet'!D13-'Balance Sheet'!C13 -> -7724.2001 | E12: ='Balance Sheet'!E13-'Balance Sheet'!D13 -> -2848.0199 | F12: ='Balance Sheet'!F13-'Balance Sheet'!E13 -> -8566.7223 | G12: ='Balance Sheet'!G13-'Balance Sheet'!F13 -> -12215.162 | H12: ='Balance Sheet'!H13-'Balance Sheet'!G13 -> -14626.082
B13: − Dividends paid | D13: =-'Income Statement'!D16 -> -1287.7172 | E13: =-'Income Statement'!E16 -> -1950.8774 | F13: =-'Income Statement'!F16 -> -2363.516 | G13: =-'Income Statement'!G16 -> -2841.5039 | H13: =-'Income Statement'!H16 -> -3396.8817
B14: Cash from financing | D14: =D12+D13 -> -9011.9172 | E14: =E12+E13 -> -4798.8973 | F14: =F12+F13 -> -10930.238 | G14: =G12+G13 -> -15056.666 | H14: =H12+H13 -> -18022.964
B15: Net change in cash | D15: =D9+D11+D14 -> -7086 | E15: =E9+E11+E14 -> 0 | F15: =F9+F11+F14 -> 0 | G15: =G9+G11+G14 -> 0 | H15: =H9+H11+H14 -> 0
B16: Opening cash | D16: ='Balance Sheet'!C8 -> 22086 | E16: =D17 -> 15000 | F16: =E17 -> 15000 | G16: =F17 -> 15000 | H16: =G17 -> 15000
B17: Closing cash | D17: =D16+D15 -> 15000 | E17: =E16+E15 -> 15000 | F17: =F16+F15 -> 15000 | G17: =G16+G15 -> 15000 | H17: =H16+H15 -> 15000
B19: Cash is the balancing plug (CF closing cash). Balance check row must be 0 in every year.

Sheet Valuation
A1: TMPV — DCF VALUATION (FCFF)
B2: (All figures in ₹ Crores except per-share data)
B3: 1. COST OF CAPITAL (WACC)
B4: Cost of equity (Ke) | C4: =Assumptions!C5+Assumptions!C13*Assumptions!C6 -> 0.134
B5: Post-tax cost of debt | C5: =Assumptions!C14*(1-Assumptions!C12) -> 0.04875
B6: Market value of equity (₹ Cr) | C6: =Assumptions!C10*Assumptions!C11 -> 121973.5
B7: Debt (FY26 borrowings, ₹ Cr) | C7: ='Balance Sheet'!C13 -> 79109
B8: Weight of equity | C8: =C6/(C6+C7) -> 0.60658436
B9: WACC | C9: =C8*C4+(1-C8)*C5 -> 0.10046132
B10: Terminal growth (g) | C10: =Assumptions!C15 -> 0.03
B12: 2. FREE CASH FLOW TO FIRM (FCFF)
D13: FY27E | E13: FY28E | F13: FY29E | G13: FY30E | H13: FY31E
B14: EBIT | D14: ='Income Statement'!D9 -> 12901.825 | E14: ='Income Statement'!E9 -> 18210.372 | F14: ='Income Statement'!F9 -> 21535.871 | G14: ='Income Statement'!G9 -> 25156.316 | H14: ='Income Statement'!H9 -> 29282.249
B15: NOPAT (EBIT × (1−t)) | D15: =D14*(1-Assumptions!$C$12) -> 9676.3686 | E15: =E14*(1-Assumptions!$C$12) -> 13657.779 | F15: =F14*(1-Assumptions!$C$12) -> 16151.903 | G15: =G14*(1-Assumptions!$C$12) -> 18867.237 | H15: =H14*(1-Assumptions!$C$12) -> 21961.687
B16: + Depreciation | D16: ='Income Statement'!D8 -> 22804.1 | E16: ='Income Statement'!E8 -> 24016.582 | F16: ='Income Statement'!F8 -> 25356.157 | G16: ='Income Statement'!G8 -> 26318.342 | H16: ='Income Statement'!H8 -> 27116.071
B17: − Capex | D17: =-'Income Statement'!D4*Assumptions!D25 -> -33826.666 | E17: =-'Income Statement'!E4*Assumptions!E25 -> -36194.532 | F17: =-'Income Statement'!F4*Assumptions!F25 -> -34103.293 | G17: =-'Income Statement'!G4*Assumptions!G25 -> -33570.429 | H17: =-'Income Statement'!H4*Assumptions!H25 -> -35248.95
B18: − Increase in working capital | D18: =-(('Balance Sheet'!D6+'Balance Sheet'!D7-'Balance Sheet'!D14)-('Balance Sheet'!C6+'Balance Sheet'!C7-'Balance Sheet'!C14)) -> 4363.7017 | E18: =-(('Balance Sheet'!E6+'Balance Sheet'!E7-'Balance Sheet'!E14)-('Balance Sheet'!D6+'Balance Sheet'!D7-'Balance Sheet'!D14)) -> 3970.9983 | F18: =-(('Balance Sheet'!F6+'Balance Sheet'!F7-'Balance Sheet'!F14)-('Balance Sheet'!E6+'Balance Sheet'!E7-'Balance Sheet'!E14)) -> 3920.6005 | G18: =-(('Balance Sheet'!G6+'Balance Sheet'!G7-'Balance Sheet'!G14)-('Balance Sheet'!F6+'Balance Sheet'!F7-'Balance Sheet'!F14)) -> 3365.3935 | H18: =-(('Balance Sheet'!H6+'Balance Sheet'!H7-'Balance Sheet'!H14)-('Balance Sheet'!G6+'Balance Sheet'!G7-'Balance Sheet'!G14)) -> 3509.9646
B19: FCFF | D19: =SUM(D15:D18) -> 3017.5047 | E19: =SUM(E15:E18) -> 5450.8273 | F19: =SUM(F15:F18) -> 11325.368 | G19: =SUM(G15:G18) -> 14980.543 | H19: =SUM(H15:H18) -> 17338.772
B20: Discount factor | D20: =1/(1+$C$9)^0.5 -> 0.95326272 | E20: =1/(1+$C$9)^1.5 -> 0.86623919 | F20: =1/(1+$C$9)^2.5 -> 0.78716006 | G20: =1/(1+$C$9)^3.5 -> 0.71530007 | H20: =1/(1+$C$9)^4.5 -> 0.65000019
B21: PV of FCFF | D21: =D19*D20 -> 2876.4748 | E21: =E19*E20 -> 4721.7202 | F21: =F19*F20 -> 8914.877 | G21: =G19*G20 -> 10715.584 | H21: =H19*H20 -> 11270.205
B23: 3. DCF VALUATION
B24: PV of explicit FCFF (FY27–31) | C24: =SUM(D21:H21) -> 38498.861
B25: Terminal value at FY31 | C25: =H19*(1+C10)/(C9-C10) -> 253457.31
B26: PV of terminal value | C26: =C25*H20 -> 164747.3
B27: Enterprise value | C27: =C24+C26 -> 203246.16
B28: + Cash & equivalents (FY26) | C28: =Assumptions!C16 -> 22086
B29: + Investments (FY26) | C29: ='Balance Sheet'!C5 -> 26313
B30: − Borrowings (FY26) | C30: =-'Balance Sheet'!C13 -> -79109
B31: EQUITY VALUE (₹ Cr) | C31: =SUM(C27:C30) -> 172536.16
B32: Shares outstanding (Cr) | C32: =Assumptions!C11 -> 368.5
B33: INTRINSIC VALUE PER SHARE (₹) | C33: =C31/C32 -> 468.2121
B34: Current market price (₹) | C34: =Assumptions!C10 -> 331
B35: Upside / (downside) | C35: =C33/C34-1 -> 0.41453807
B36: Terminal value as % of enterprise value | C36: =C26/C27 -> 0.81058013 | J36: ~80% of EV sits in the terminal value — read the DCF with the sensitivity grid and scenarios, not as a point estimate
B37: 4. DCF SENSITIVITY — INTRINSIC VALUE PER SHARE (₹)
C40: WACC \ g | D40: =$C$10+-0.01 -> 0.02 | E40: =$C$10+-0.005 -> 0.025 | F40: =$C$10+0 -> 0.03 | G40: =$C$10+0.005 -> 0.035 | H40: =$C$10+0.01 -> 0.04
C41: =$C$9+-0.01 -> 0.090461317 | D41: =($D$19/(1+$C41)^0.5+$E$19/(1+$C41)^1.5+$F$19/(1+$C41)^2.5+$G$19/(1+$C41)^3.5+$H$19/(1+$C41)^4.5+$H$19*(1+D$40)/(($C41-D$40)*(1+$C41)^4.5)+$C$28+$C$29+$C$30)/$C$32 -> 485.43475 | E41: =($D$19/(1+$C41)^0.5+$E$19/(1+$C41)^1.5+$F$19/(1+$C41)^2.5+$G$19/(1+$C41)^3.5+$H$19/(1+$C41)^4.5+$H$19*(1+E$40)/(($C41-E$40)*(1+$C41)^4.5)+$C$28+$C$29+$C$30)/$C$32 -> 523.10335 | F41: =($D$19/(1+$C41)^0.5+$E$19/(1+$C41)^1.5+$F$19/(1+$C41)^2.5+$G$19/(1+$C41)^3.5+$H$19/(1+$C41)^4.5+$H$19*(1+F$40)/(($C41-F$40)*(1+$C41)^4.5)+$C$28+$C$29+$C$30)/$C$32 -> 567.00215 | G41: =($D$19/(1+$C41)^0.5+$E$19/(1+$C41)^1.5+$F$19/(1+$C41)^2.5+$G$19/(1+$C41)^3.5+$H$19/(1+$C41)^4.5+$H$19*(1+G$40)/(($C41-G$40)*(1+$C41)^4.5)+$C$28+$C$29+$C$30)/$C$32 -> 618.81615 | H41: =($D$19/(1+$C41)^0.5+$E$19/(1+$C41)^1.5+$F$19/(1+$C41)^2.5+$G$19/(1+$C41)^3.5+$H$19/(1+$C41)^4.5+$H$19*(1+H$40)/(($C41-H$40)*(1+$C41)^4.5)+$C$28+$C$29+$C$30)/$C$32 -> 680.89822
C42: =$C$9+-0.005 -> 0.095461317 | D42: =($D$19/(1+$C42)^0.5+$E$19/(1+$C42)^1.5+$F$19/(1+$C42)^2.5+$G$19/(1+$C42)^3.5+$H$19/(1+$C42)^4.5+$H$19*(1+D$40)/(($C42-D$40)*(1+$C42)^4.5)+$C$28+$C$29+$C$30)/$C$32 -> 444.57838 | E42: =($D$19/(1+$C42)^0.5+$E$19/(1+$C42)^1.5+$F$19/(1+$C42)^2.5+$G$19/(1+$C42)^3.5+$H$19/(1+$C42)^4.5+$H$19*(1+E$40)/(($C42-E$40)*(1+$C42)^4.5)+$C$28+$C$29+$C$30)/$C$32 -> 476.73616 | F42: =($D$19/(1+$C42)^0.5+$E$19/(1+$C42)^1.5+$F$19/(1+$C42)^2.5+$G$19/(1+$C42)^3.5+$H$19/(1+$C42)^4.5+$H$19*(1+F$40)/(($C42-F$40)*(1+$C42)^4.5)+$C$28+$C$29+$C$30)/$C$32 -> 513.80642 | G42: =($D$19/(1+$C42)^0.5+$E$19/(1+$C42)^1.5+$F$19/(1+$C42)^2.5+$G$19/(1+$C42)^3.5+$H$19/(1+$C42)^4.5+$H$19*(1+G$40)/(($C42-G$40)*(1+$C42)^4.5)+$C$28+$C$29+$C$30)/$C$32 -> 557.00793 | H42: =($D$19/(1+$C42)^0.5+$E$19/(1+$C42)^1.5+$F$19/(1+$C42)^2.5+$G$19/(1+$C42)^3.5+$H$19/(1+$C42)^4.5+$H$19*(1+H$40)/(($C42-H$40)*(1+$C42)^4.5)+$C$28+$C$29+$C$30)/$C$32 -> 607.99891
C43: =$C$9+0 -> 0.10046132 | D43: =($D$19/(1+$C43)^0.5+$E$19/(1+$C43)^1.5+$F$19/(1+$C43)^2.5+$G$19/(1+$C43)^3.5+$H$19/(1+$C43)^4.5+$H$19*(1+D$40)/(($C43-D$40)*(1+$C43)^4.5)+$C$28+$C$29+$C$30)/$C$32 -> 408.847 | E43: =($D$19/(1+$C43)^0.5+$E$19/(1+$C43)^1.5+$F$19/(1+$C43)^2.5+$G$19/(1+$C43)^3.5+$H$19/(1+$C43)^4.5+$H$19*(1+E$40)/(($C43-E$40)*(1+$C43)^4.5)+$C$28+$C$29+$C$30)/$C$32 -> 436.56281 | F43: =($D$19/(1+$C43)^0.5+$E$19/(1+$C43)^1.5+$F$19/(1+$C43)^2.5+$G$19/(1+$C43)^3.5+$H$19/(1+$C43)^4.5+$H$19*(1+F$40)/(($C43-F$40)*(1+$C43)^4.5)+$C$28+$C$29+$C$30)/$C$32 -> 468.2121 | G43: =($D$19/(1+$C43)^0.5+$E$19/(1+$C43)^1.5+$F$19/(1+$C43)^2.5+$G$19/(1+$C43)^3.5+$H$19/(1+$C43)^4.5+$H$19*(1+G$40)/(($C43-G$40)*(1+$C43)^4.5)+$C$28+$C$29+$C$30)/$C$32 -> 504.6962 | H43: =($D$19/(1+$C43)^0.5+$E$19/(1+$C43)^1.5+$F$19/(1+$C43)^2.5+$G$19/(1+$C43)^3.5+$H$19/(1+$C43)^4.5+$H$19*(1+H$40)/(($C43-H$40)*(1+$C43)^4.5)+$C$28+$C$29+$C$30)/$C$32 -> 547.21459
C44: =$C$9+0.005 -> 0.10546132 | D44: =($D$19/(1+$C44)^0.5+$E$19/(1+$C44)^1.5+$F$19/(1+$C44)^2.5+$G$19/(1+$C44)^3.5+$H$19/(1+$C44)^4.5+$H$19*(1+D$40)/(($C44-D$40)*(1+$C44)^4.5)+$C$28+$C$29+$C$30)/$C$32 -> 377.34017 | E44: =($D$19/(1+$C44)^0.5+$E$19/(1+$C44)^1.5+$F$19/(1+$C44)^2.5+$G$19/(1+$C44)^3.5+$H$19/(1+$C44)^4.5+$H$19*(1+E$40)/(($C44-E$40)*(1+$C44)^4.5)+$C$28+$C$29+$C$30)/$C$32 -> 401.42767 | F44: =($D$19/(1+$C44)^0.5+$E$19/(1+$C44)^1.5+$F$19/(1+$C44)^2.5+$G$19/(1+$C44)^3.5+$H$19/(1+$C44)^4.5+$H$19*(1+F$40)/(($C44-F$40)*(1+$C44)^4.5)+$C$28+$C$29+$C$30)/$C$32 -> 428.7072 | G44: =($D$19/(1+$C44)^0.5+$E$19/(1+$C44)^1.5+$F$19/(1+$C44)^2.5+$G$19/(1+$C44)^3.5+$H$19/(1+$C44)^4.5+$H$19*(1+G$40)/(($C44-G$40)*(1+$C44)^4.5)+$C$28+$C$29+$C$30)/$C$32 -> 459.8583 | H44: =($D$19/(1+$C44)^0.5+$E$19/(1+$C44)^1.5+$F$19/(1+$C44)^2.5+$G$19/(1+$C44)^3.5+$H$19/(1+$C44)^4.5+$H$19*(1+H$40)/(($C44-H$40)*(1+$C44)^4.5)+$C$28+$C$29+$C$30)/$C$32 -> 495.76809
...

Sheet Recommendation
A1: INVESTMENT RECOMMENDATION
B2: (All figures in ₹ Crores except per-share data)
B4: RECOMMENDATION
B5: Current market price (₹) | C5: =Valuation!C34 -> 331
B6: Fair value — base case (₹) | C6: =Valuation!C72 -> 468.2121 | D6: ="Bear–Bull DCF range: ₹"&TEXT(Valuation!E81,"#,##0")&" – ₹"&TEXT(Valuation!E83,"#,##0")&"; relative cross-check ₹"&TEXT(Valuation!C61,"#,##0")&" – ₹"&TEXT(Valuation!C63,"#,##0") -> Bear–Bull DCF range: ₹335 – ₹610; relative cross-check ₹280 – ₹466
B7: Relative cross-check — base 16× (₹) | C7: =Valuation!C69 -> 372.74491
B8: Valuation verdict | C8: =Valuation!C75 -> UNDERVALUED
B9: Expected return to fair value | C9: =C6/C5-1 -> 0.41453807
B10: RATING (12 months) | C10: =IF(C9>0.15,"BUY",IF(C9>=-0.12,"HOLD","SELL")) -> BUY | D10: BUY — the DCF says the market is pricing JLR's stress as permanent. Sized for a 12-month recovery in JLR volumes/margins; the relative cross-check (₹ vs pure-India peers) is less reliable given the mix.
B12: WHY — THE FOUR PILLARS OF THE CALL
B13: Growth prospects | C13: RECOVERING | D13: FY26 was cyberattack- and tariff-hit; the model assumes revenue rebuilds at the Assumptions-tab growth path with JLR volumes normalising and India PV riding new launches/EVs.
B14: Competitive position | C14: MIXED BUT IMPROVING | D14: India #3 in PV with the EV lead (Nexon/Punch/Tiago EV franchise); JLR owns genuinely premium brands (Defender, Range Rover) but is exposed to China/EU luxury cycles.
B15: Financial strength | C15: IMPROVING | D15: Net debt ₹30,710 Cr at FY26 with a deleveraging path in the Debt Schedule (cash sweep + ₹15,000 Cr cash floor revolver); interest cover improves through the forecast.
B16: Valuation | C16: THE OPPORTUNITY | D16: ="At ~14× FY27E earnings vs pure-India peers at 22–37×, the market already prices a deep JLR discount; DCF fair value ₹"&TEXT(Valuation!C33,"#,##0")&" implies ~"&TEXT(Valuation!C35,"0%")&" upside." -> At ~14× FY27E earnings vs pure-India peers at 22–37×, the market already prices a deep JLR discount; DCF fair value ₹468 implies ~41% upside.
B18: KEY RISKS TO THE CALL
B19: Downside risks | D19: (1) JLR volume/margin recovery from the Sep-2025 cyberattack proves slower than assumed; (2) China/EU luxury demand stays weak or US tariffs escalate; (3) EV transition capex rises faster than the capex assumption; (4) FY26 baseline distortions (one-off gain excluded, but margins depressed) make forecast error larger than usual.
B20: Upside risks (what could make BUY conservative) | D20: (1) JLR margins recover faster on Defender/Range Rover mix; (2) India PV share gains accelerate with EV leadership; (3) a re-rating toward even the Bear-case relative multiple adds to DCF-driven upside.
B22: WHAT TO DO — ACTION TRIGGERS
B23: If you own the stock | D23: Keep it — the DCF says intrinsic value is well above price and the balance sheet is deleveraging.
B24: If you want to buy | D24: Current price (~₹331) is already ~34% below DCF fair value; accumulating here is consistent with the model. Averaging on JLR-news dips improves the entry.
B25: Re-rate the call UP if | D25: JLR EBIT margin normalises ahead of plan, India PV market share crosses its recent highs, or net debt falls faster than the Debt Schedule path.
B26: Re-rate the call DOWN if | D26: JLR volumes fail to recover by mid-FY27, EBITDA margin undershoots the Assumptions path, or net debt rises instead of falling.
B28: Bottom line: a recovering franchise priced for permanent stress. BUY.
H49: Series
H50: Market price (₹) | I50: =Valuation!C34 -> 331
H51: Intrinsic value, DCF (₹) | I51: =Valuation!C33 -> 468.2121

Sheet Charts & Trends
B1: CHARTS & TREND ANALYSIS
B2: All series are formula-linked to the model sheets. FY26A PAT shown on a normalized basis (excl. one-off demerger gain).
B40: CHART DATA (linked to model — do not type over)
C42: FY23 | D42: FY24 | E42: FY25 | F42: FY26A | G42: FY27E | H42: FY28E | I42: FY29E | J42: FY30E | K42: FY31E
B43: Revenue (₹ Cr) | C43: ='Historical Data'!K6 -> 345967 | D43: ='Historical Data'!L6 -> 434016 | E43: ='Historical Data'!M6 -> 366094 | F43: ='Historical Data'!N6 -> 335582 | G43: ='Income Statement'!D4 -> 375851.84 | H43: ='Income Statement'!E4 -> 402161.47 | I43: ='Income Statement'!F4 -> 426291.16 | J43: ='Income Statement'!G4 -> 447605.71 | K43: ='Income Statement'!H4 -> 469986
C45: FY23 | D45: FY24 | E45: FY25 | F45: FY26A | G45: FY27E | H45: FY28E | I45: FY29E | J45: FY30E | K45: FY31E
B46: EBITDA margin % | C46: ='Historical Data'!K8/'Historical Data'!K6 -> 0.091962528 | D46: ='Historical Data'!L8/'Historical Data'!L6 -> 0.13319555 | E46: ='Historical Data'!M8/'Historical Data'!M6 -> 0.13109475 | F46: ='Historical Data'!N8/'Historical Data'!N6 -> 0.055780703 | G46: ='Income Statement'!D7 -> 0.095 | H46: ='Income Statement'!E7 -> 0.105 | I46: ='Income Statement'!F7 -> 0.11 | J46: ='Income Statement'!G7 -> 0.115 | K46: ='Income Statement'!H7 -> 0.12
C48: FY26A | D48: FY27E | E48: FY28E | F48: FY29E | G48: FY30E | H48: FY31E
B49: PAT (₹ Cr, FY26A normalized) | C49: ='Income Statement'!C26 -> -3646 | D49: ='Income Statement'!D14 -> 8584.7811 | E49: ='Income Statement'!E14 -> 13005.849 | F49: ='Income Statement'!F14 -> 15756.774 | G49: ='Income Statement'!G14 -> 18943.359 | H49: ='Income Statement'!H14 -> 22645.878
C51: FY26A | D51: FY27E | E51: FY28E | F51: FY29E | G51: FY30E | H51: FY31E
B52: FCFF (₹ Cr) | D52: =Valuation!D19 -> 3017.5047 | E52: =Valuation!E19 -> 5450.8273 | F52: =Valuation!F19 -> 11325.368 | G52: =Valuation!G19 -> 14980.543 | H52: =Valuation!H19 -> 17338.772
B53: Net debt (₹ Cr) | C53: ='Ratio Analysis'!C15 -> 30710 | D53: ='Ratio Analysis'!D15 -> 30071.8 | E53: ='Ratio Analysis'!E15 -> 27223.78 | F53: ='Ratio Analysis'!F15 -> 18657.058 | G53: ='Ratio Analysis'!G15 -> 6441.8956 | H53: ='Ratio Analysis'!H15 -> -8184.1866

Sheet Checks
A1: MODEL CHECKS
B2: All controls must show PASS. Values are the maximum absolute difference across FY27E–FY31E (₹ Cr).
B4: CONTROL | C4: MAX |DIFF| | D4: STATUS | E4: WHAT IT PROVES
B5: Balance sheet ties (assets − equity & liabilities) | C5: {=MAX(ABS('Balance Sheet'!C16:H16))} -> 0 | D5: =IF(C5<0.01,"PASS","FAIL") -> PASS | E5: Core integrity check — cash is the CF plug, so this must be 0 by construction.
